Workbook

Sheet Handle
A1: HANDLE ($) — US Online Sports Betting
A2: Linked dynamically to Raw Data via SUMIFS. 18 operator-reporting US states, online channel, all time. Months where a state did not publish are excluded for that state — see the Coverage sheet.
A4: HANDLE ($) | B4: 43313 | C4: 43344 | D4: 43374 | E4: 43405 | F4: 43435 | G4: 43466 | H4: 43497 | I4: 43525 | J4: 43556 | K4: 43586 | L4: 43617 | M4: 43647 | N4: 43678 | O4: 43709 | P4: 43739 | Q4: 43770 | R4: 43800 | S4: 43831 | T4: 43862 | U4: 43891 | V4: 43922 | W4: 43952 | X4: 43983 | Y4: 44013 | Z4: 44044 | AA4: 44075 | AB4: 44105 | AC4: 44136 | AD4: 44166 | AE4: 44197 | AF4: 44228 | AG4: 44256 | AH4: 44287 | AI4: 44317 | AJ4: 44348 | AK4: 44378 | AL4: 44409 | AM4: 44440 | AN4: 44470 | AO4: 44501 | AP4: 44531 | AQ4: 44562 | AR4: 44593 | AS4: 44621 | AT4: 44652 | AU4: 44682 | AV4: 44713 | AW4: 44743 | AX4: 44774 | AY4: 44805 | AZ4: 44835 | BA4: 44866 | BB4: 44896 | BC4: 44927 | BD4: 44958 | BE4: 44986 | BF4: 45017 | BG4: 45047 | BH4: 45078 | BI4: 45108 | BJ4: 45139 | BK4: 45170 | BL4: 45200 | BM4: 45231 | BN4: 45261 | BO4: 45292 | BP4: 45323 | BQ4: 45352 | BR4: 45383 | BS4: 45413 | BT4: 45444 | BU4: 45474 | BV4: 45505 | BW4: 45536 | BX4: 45566 | BY4: 45597 | BZ4: 45627 | CA4: 45658 | CB4: 45689 | CC4: 45717 | CD4: 45748 | CE4: 45778 | CF4: 45809 | CG4: 45839 | CH4: 45870 | CI4: 45901 | CJ4: 45931 | CK4: 45962 | CL4: 45992 | CM4: 46023 | CN4: 46054 | CO4: 46082
A5: FanDuel | B5: =SUMIFS('Raw Data'!$E:$E,'Raw Data'!$B:$B,$A5,'Raw Data'!$D:$D,B$4) | C5: =SUMIFS('Raw Data'!$E:$E,'Raw Data'!$B:$B,$A5,'Raw Data'!$D:$D,C$4) | D5: =SUMIFS('Raw Data'!$E:$E,'Raw Data'!$B:$B,$A5,'Raw Data'!$D:$D,D$4) | E5: =SUMIFS('Raw Data'!$E:$E,'Raw Data'!$B:$B,$A5,'Raw Data'!$D:$D,E$4) | F5: =SUMIFS('Raw Data'!$E:$E,'Raw Data'!$B:$B,$A5,'Raw Data'!$D:$D,F$4) | G5: =SUMIFS('Raw Data'!$E:$E,'Raw Data'!$B:$B,$A5,'Raw Data'!$D:$D,G$4) | H5: =SUMIFS('Raw Data'!$E:$E,'Raw Data'!$B:$B,$A5,'Raw Data'!$D:$D,H$4) | I5: =SUMIFS('Raw Data'!$E:$E,'Raw Data'!$B:$B,$A5,'Raw Data'!$D:$D,I$4) | ... CO5: =SUMIFS('Raw Data'!$E:$E,'Raw Data'!$B:$B,$A5,'Raw Data'!$D:$D,CO$4)
A6: DraftKings | B6: =SUMIFS('Raw Data'!$E:$E,'Raw Data'!$B:$B,$A6,'Raw Data'!$D:$D,B$4) | C6: =SUMIFS('Raw Data'!$E:$E,'Raw Data'!$B:$B,$A6,'Raw Data'!$D:$D,C$4) | D6: =SUMIFS('Raw Data'!$E:$E,'Raw Data'!$B:$B,$A6,'Raw Data'!$D:$D,D$4) | E6: =SUMIFS('Raw Data'!$E:$E,'Raw Data'!$B:$B,$A6,'Raw Data'!$D:$D,E$4) | F6: =SUMIFS('Raw Data'!$E:$E,'Raw Data'!$B:$B,$A6,'Raw Data'!$D:$D,F$4) | G6: =SUMIFS('Raw Data'!$E:$E,'Raw Data'!$B:$B,$A6,'Raw Data'!$D:$D,G$4) | H6: =SUMIFS('Raw Data'!$E:$E,'Raw Data'!$B:$B,$A6,'Raw Data'!$D:$D,H$4) | I6: =SUMIFS('Raw Data'!$E:$E,'Raw Data'!$B:$B,$A6,'Raw Data'!$D:$D,I$4) | ... CO6: =SUMIFS('Raw Data'!$E:$E,'Raw Data'!$B:$B,$A6,'Raw Data'!$D:$D,CO$4)
A7: BetMGM | B7: =SUMIFS('Raw Data'!$E:$E,'Raw Data'!$B:$B,$A7,'Raw Data'!$D:$D,B$4) | C7: =SUMIFS('Raw Data'!$E:$E,'Raw Data'!$B:$B,$A7,'Raw Data'!$D:$D,C$4) | D7: =SUMIFS('Raw Data'!$E:$E,'Raw Data'!$B:$B,$A7,'Raw Data'!$D:$D,D$4) | E7: =SUMIFS('Raw Data'!$E:$E,'Raw Data'!$B:$B,$A7,'Raw Data'!$D:$D,E$4) | F7: =SUMIFS('Raw Data'!$E:$E,'Raw Data'!$B:$B,$A7,'Raw Data'!$D:$D,F$4) | G7: =SUMIFS('Raw Data'!$E:$E,'Raw Data'!$B:$B,$A7,'Raw Data'!$D:$D,G$4) | H7: =SUMIFS('Raw Data'!$E:$E,'Raw Data'!$B:$B,$A7,'Raw Data'!$D:$D,H$4) | I7: =SUMIFS('Raw Data'!$E:$E,'Raw Data'!$B:$B,$A7,'Raw Data'!$D:$D,I$4) | ... CO7: =SUMIFS('Raw Data'!$E:$E,'Raw Data'!$B:$B,$A7,'Raw Data'!$D:$D,CO$4)
A8: Fanatics | B8: =SUMIFS('Raw Data'!$E:$E,'Raw Data'!$B:$B,$A8,'Raw Data'!$D:$D,B$4) | C8: =SUMIFS('Raw Data'!$E:$E,'Raw Data'!$B:$B,$A8,'Raw Data'!$D:$D,C$4) | D8: =SUMIFS('Raw Data'!$E:$E,'Raw Data'!$B:$B,$A8,'Raw Data'!$D:$D,D$4) | E8: =SUMIFS('Raw Data'!$E:$E,'Raw Data'!$B:$B,$A8,'Raw Data'!$D:$D,E$4) | F8: =SUMIFS('Raw Data'!$E:$E,'Raw Data'!$B:$B,$A8,'Raw Data'!$D:$D,F$4) | G8: =SUMIFS('Raw Data'!$E:$E,'Raw Data'!$B:$B,$A8,'Raw Data'!$D:$D,G$4) | H8: =SUMIFS('Raw Data'!$E:$E,'Raw Data'!$B:$B,$A8,'Raw Data'!$D:$D,H$4) | I8: =SUMIFS('Raw Data'!$E:$E,'Raw Data'!$B:$B,$A8,'Raw Data'!$D:$D,I$4) | ... CO8: =SUMIFS('Raw Data'!$E:$E,'Raw Data'!$B:$B,$A8,'Raw Data'!$D:$D,CO$4)
A9: Caesars | B9: =SUMIFS('Raw Data'!$E:$E,'Raw Data'!$B:$B,$A9,'Raw Data'!$D:$D,B$4) | C9: =SUMIFS('Raw Data'!$E:$E,'Raw Data'!$B:$B,$A9,'Raw Data'!$D:$D,C$4) | D9: =SUMIFS('Raw Data'!$E:$E,'Raw Data'!$B:$B,$A9,'Raw Data'!$D:$D,D$4) | E9: =SUMIFS('Raw Data'!$E:$E,'Raw Data'!$B:$B,$A9,'Raw Data'!$D:$D,E$4) | F9: =SUMIFS('Raw Data'!$E:$E,'Raw Data'!$B:$B,$A9,'Raw Data'!$D:$D,F$4) | G9: =SUMIFS('Raw Data'!$E:$E,'Raw Data'!$B:$B,$A9,'Raw Data'!$D:$D,G$4) | H9: =SUMIFS('Raw Data'!$E:$E,'Raw Data'!$B:$B,$A9,'Raw Data'!$D:$D,H$4) | I9: =SUMIFS('Raw Data'!$E:$E,'Raw Data'!$B:$B,$A9,'Raw Data'!$D:$D,I$4) | ... CO9: =SUMIFS('Raw Data'!$E:$E,'Raw Data'!$B:$B,$A9,'Raw Data'!$D:$D,CO$4)
A10: ESPN Bet | B10: =SUMIFS('Raw Data'!$E:$E,'Raw Data'!$B:$B,$A10,'Raw Data'!$D:$D,B$4) | C10: =SUMIFS('Raw Data'!$E:$E,'Raw Data'!$B:$B,$A10,'Raw Data'!$D:$D,C$4) | D10: =SUMIFS('Raw Data'!$E:$E,'Raw Data'!$B:$B,$A10,'Raw Data'!$D:$D,D$4) | E10: =SUMIFS('Raw Data'!$E:$E,'Raw Data'!$B:$B,$A10,'Raw Data'!$D:$D,E$4) | F10: =SUMIFS('Raw Data'!$E:$E,'Raw Data'!$B:$B,$A10,'Raw Data'!$D:$D,F$4) | G10: =SUMIFS('Raw Data'!$E:$E,'Raw Data'!$B:$B,$A10,'Raw Data'!$D:$D,G$4) | H10: =SUMIFS('Raw Data'!$E:$E,'Raw Data'!$B:$B,$A10,'Raw Data'!$D:$D,H$4) | I10: =SUMIFS('Raw Data'!$E:$E,'Raw Data'!$B:$B,$A10,'Raw Data'!$D:$D,I$4) | ... CO10: =SUMIFS('Raw Data'!$E:$E,'Raw Data'!$B:$B,$A10,'Raw Data'!$D:$D,CO$4)
A11: Others | B11: =SUMIFS('Raw Data'!$E:$E,'Raw Data'!$B:$B,$A11,'Raw Data'!$D:$D,B$4) | C11: =SUMIFS('Raw Data'!$E:$E,'Raw Data'!$B:$B,$A11,'Raw Data'!$D:$D,C$4) | D11: =SUMIFS('Raw Data'!$E:$E,'Raw Data'!$B:$B,$A11,'Raw Data'!$D:$D,D$4) | E11: =SUMIFS('Raw Data'!$E:$E,'Raw Data'!$B:$B,$A11,'Raw Data'!$D:$D,E$4) | F11: =SUMIFS('Raw Data'!$E:$E,'Raw Data'!$B:$B,$A11,'Raw Data'!$D:$D,F$4) | G11: =SUMIFS('Raw Data'!$E:$E,'Raw Data'!$B:$B,$A11,'Raw Data'!$D:$D,G$4) | H11: =SUMIFS('Raw Data'!$E:$E,'Raw Data'!$B:$B,$A11,'Raw Data'!$D:$D,H$4) | I11: =SUMIFS('Raw Data'!$E:$E,'Raw Data'!$B:$B,$A11,'Raw Data'!$D:$D,I$4) | ... CO11: =SUMIFS('Raw Data'!$E:$E,'Raw Data'!$B:$B,$A11,'Raw Data'!$D:$D,CO$4)
A12: Total | B12: =SUM(B5:B11) | C12: =SUM(C5:C11) | D12: =SUM(D5:D11) | E12: =SUM(E5:E11) | F12: =SUM(F5:F11) | G12: =SUM(G5:G11) | H12: =SUM(H5:H11) | I12: =SUM(I5:I11) | ... CO12: =SUM(CO5:CO11)
A15: HANDLE ($) — % MARKET SHARE | B15: 43313 | C15: 43344 | D15: 43374 | E15: 43405 | F15: 43435 | G15: 43466 | H15: 43497 | I15: 43525 | J15: 43556 | K15: 43586 | L15: 43617 | M15: 43647 | N15: 43678 | O15: 43709 | P15: 43739 | Q15: 43770 | R15: 43800 | S15: 43831 | T15: 43862 | U15: 43891 | V15: 43922 | W15: 43952 | X15: 43983 | Y15: 44013 | Z15: 44044 | AA15: 44075 | AB15: 44105 | AC15: 44136 | AD15: 44166 | AE15: 44197 | AF15: 44228 | AG15: 44256 | AH15: 44287 | AI15: 44317 | AJ15: 44348 | AK15: 44378 | AL15: 44409 | AM15: 44440 | AN15: 44470 | AO15: 44501 | AP15: 44531 | AQ15: 44562 | AR15: 44593 | AS15: 44621 | AT15: 44652 | AU15: 44682 | AV15: 44713 | AW15: 44743 | AX15: 44774 | AY15: 44805 | AZ15: 44835 | BA15: 44866 | BB15: 44896 | BC15: 44927 | BD15: 44958 | BE15: 44986 | BF15: 45017 | BG15: 45047 | BH15: 45078 | BI15: 45108 | BJ15: 45139 | BK15: 45170 | BL15: 45200 | BM15: 45231 | BN15: 45261 | BO15: 45292 | BP15: 45323 | BQ15: 45352 | BR15: 45383 | BS15: 45413 | BT15: 45444 | BU15: 45474 | BV15: 45505 | BW15: 45536 | BX15: 45566 | BY15: 45597 | BZ15: 45627 | CA15: 45658 | CB15: 45689 | CC15: 45717 | CD15: 45748 | CE15: 45778 | CF15: 45809 | CG15: 45839 | CH15: 45870 | CI15: 45901 | CJ15: 45931 | CK15: 45962 | CL15: 45992 | CM15: 46023 | CN15: 46054 | CO15: 46082
A16: FanDuel | B16: =IFERROR(B5/B12,"") | C16: =IFERROR(C5/C12,"") | D16: =IFERROR(D5/D12,"") | E16: =IFERROR(E5/E12,"") | F16: =IFERROR(F5/F12,"") | G16: =IFERROR(G5/G12,"") | H16: =IFERROR(H5/H12,"") | I16: =IFERROR(I5/I12,"") | ... CO16: =IFERROR(CO5/CO12,"")
A17: DraftKings | B17: =IFERROR(B6/B12,"") | C17: =IFERROR(C6/C12,"") | D17: =IFERROR(D6/D12,"") | E17: =IFERROR(E6/E12,"") | F17: =IFERROR(F6/F12,"") | G17: =IFERROR(G6/G12,"") | H17: =IFERROR(H6/H12,"") | I17: =IFERROR(I6/I12,"") | ... CO17: =IFERROR(CO6/CO12,"")
A18: BetMGM | B18: =IFERROR(B7/B12,"") | C18: =IFERROR(C7/C12,"") | D18: =IFERROR(D7/D12,"") | E18: =IFERROR(E7/E12,"") | F18: =IFERROR(F7/F12,"") | G18: =IFERROR(G7/G12,"") | H18: =IFERROR(H7/H12,"") | I18: =IFERROR(I7/I12,"") | ... CO18: =IFERROR(CO7/CO12,"")
A19: Fanatics | B19: =IFERROR(B8/B12,"") | C19: =IFERROR(C8/C12,"") | D19: =IFERROR(D8/D12,"") | E19: =IFERROR(E8/E12,"") | F19: =IFERROR(F8/F12,"") | G19: =IFERROR(G8/G12,"") | H19: =IFERROR(H8/H12,"") | I19: =IFERROR(I8/I12,"") | ... CO19: =IFERROR(CO8/CO12,"")
A20: Caesars | B20: =IFERROR(B9/B12,"") | C20: =IFERROR(C9/C12,"") | D20: =IFERROR(D9/D12,"") | E20: =IFERROR(E9/E12,"") | F20: =IFERROR(F9/F12,"") | G20: =IFERROR(G9/G12,"") | H20: =IFERROR(H9/H12,"") | I20: =IFERROR(I9/I12,"") | ... CO20: =IFERROR(CO9/CO12,"")
A21: ESPN Bet | B21: =IFERROR(B10/B12,"") | C21: =IFERROR(C10/C12,"") | D21: =IFERROR(D10/D12,"") | E21: =IFERROR(E10/E12,"") | F21: =IFERROR(F10/F12,"") | G21: =IFERROR(G10/G12,"") | H21: =IFERROR(H10/H12,"") | I21: =IFERROR(I10/I12,"") | ... CO21: =IFERROR(CO10/CO12,"")
A22: Others | B22: =IFERROR(B11/B12,"") | C22: =IFERROR(C11/C12,"") | D22: =IFERROR(D11/D12,"") | E22: =IFERROR(E11/E12,"") | F22: =IFERROR(F11/F12,"") | G22: =IFERROR(G11/G12,"") | H22: =IFERROR(H11/H12,"") | I22: =IFERROR(I11/I12,"") | ... CO22: =IFERROR(CO11/CO12,"")
A23: Total | B23: =IFERROR(B12/B12,"") | C23: =IFERROR(C12/C12,"") | D23: =IFERROR(D12/D12,"") | E23: =IFERROR(E12/E12,"") | F23: =IFERROR(F12/F12,"") | G23: =IFERROR(G12/G12,"") | H23: =IFERROR(H12/H12,"") | I23: =IFERROR(I12/I12,"") | ... CO23: =IFERROR(CO12/CO12,"")

Sheet GGR
A1: GGR ($) — US Online Sports Betting
A2: Linked dynamically to Raw Data via SUMIFS. 18 operator-reporting US states, online channel, all time. Months where a state did not publish are excluded for that state — see the Coverage sheet.
A4: GGR ($) | B4: 43313 | C4: 43344 | D4: 43374 | E4: 43405 | F4: 43435 | G4: 43466 | H4: 43497 | I4: 43525 | J4: 43556 | K4: 43586 | L4: 43617 | M4: 43647 | N4: 43678 | O4: 43709 | P4: 43739 | Q4: 43770 | R4: 43800 | S4: 43831 | T4: 43862 | U4: 43891 | V4: 43922 | W4: 43952 | X4: 43983 | Y4: 44013 | Z4: 44044 | AA4: 44075 | AB4: 44105 | AC4: 44136 | AD4: 44166 | AE4: 44197 | AF4: 44228 | AG4: 44256 | AH4: 44287 | AI4: 44317 | AJ4: 44348 | AK4: 44378 | AL4: 44409 | AM4: 44440 | AN4: 44470 | AO4: 44501 | AP4: 44531 | AQ4: 44562 | AR4: 44593 | AS4: 44621 | AT4: 44652 | AU4: 44682 | AV4: 44713 | AW4: 44743 | AX4: 44774 | AY4: 44805 | AZ4: 44835 | BA4: 44866 | BB4: 44896 | BC4: 44927 | BD4: 44958 | BE4: 44986 | BF4: 45017 | BG4: 45047 | BH4: 45078 | BI4: 45108 | BJ4: 45139 | BK4: 45170 | BL4: 45200 | BM4: 45231 | BN4: 45261 | BO4: 45292 | BP4: 45323 | BQ4: 45352 | BR4: 45383 | BS4: 45413 | BT4: 45444 | BU4: 45474 | BV4: 45505 | BW4: 45536 | BX4: 45566 | BY4: 45597 | BZ4: 45627 | CA4: 45658 | CB4: 45689 | CC4: 45717 | CD4: 45748 | CE4: 45778 | CF4: 45809 | CG4: 45839 | CH4: 45870 | CI4: 45901 | CJ4: 45931 | CK4: 45962 | CL4: 45992 | CM4: 46023 | CN4: 46054 | CO4: 46082
A5: FanDuel | B5: =SUMIFS('Raw Data'!$F:$F,'Raw Data'!$B:$B,$A5,'Raw Data'!$D:$D,B$4) | C5: =SUMIFS('Raw Data'!$F:$F,'Raw Data'!$B:$B,$A5,'Raw Data'!$D:$D,C$4) | D5: =SUMIFS('Raw Data'!$F:$F,'Raw Data'!$B:$B,$A5,'Raw Data'!$D:$D,D$4) | E5: =SUMIFS('Raw Data'!$F:$F,'Raw Data'!$B:$B,$A5,'Raw Data'!$D:$D,E$4) | F5: =SUMIFS('Raw Data'!$F:$F,'Raw Data'!$B:$B,$A5,'Raw Data'!$D:$D,F$4) | G5: =SUMIFS('Raw Data'!$F:$F,'Raw Data'!$B:$B,$A5,'Raw Data'!$D:$D,G$4) | H5: =SUMIFS('Raw Data'!$F:$F,'Raw Data'!$B:$B,$A5,'Raw Data'!$D:$D,H$4) | I5: =SUMIFS('Raw Data'!$F:$F,'Raw Data'!$B:$B,$A5,'Raw Data'!$D:$D,I$4) | ... CO5: =SUMIFS('Raw Data'!$F:$F,'Raw Data'!$B:$B,$A5,'Raw Data'!$D:$D,CO$4)
A6: DraftKings | B6: =SUMIFS('Raw Data'!$F:$F,'Raw Data'!$B:$B,$A6,'Raw Data'!$D:$D,B$4) | C6: =SUMIFS('Raw Data'!$F:$F,'Raw Data'!$B:$B,$A6,'Raw Data'!$D:$D,C$4) | D6: =SUMIFS('Raw Data'!$F:$F,'Raw Data'!$B:$B,$A6,'Raw Data'!$D:$D,D$4) | E6: =SUMIFS('Raw Data'!$F:$F,'Raw Data'!$B:$B,$A6,'Raw Data'!$D:$D,E$4) | F6: =SUMIFS('Raw Data'!$F:$F,'Raw Data'!$B:$B,$A6,'Raw Data'!$D:$D,F$4) | G6: =SUMIFS('Raw Data'!$F:$F,'Raw Data'!$B:$B,$A6,'Raw Data'!$D:$D,G$4) | H6: =SUMIFS('Raw Data'!$F:$F,'Raw Data'!$B:$B,$A6,'Raw Data'!$D:$D,H$4) | I6: =SUMIFS('Raw Data'!$F:$F,'Raw Data'!$B:$B,$A6,'Raw Data'!$D:$D,I$4) | ... CO6: =SUMIFS('Raw Data'!$F:$F,'Raw Data'!$B:$B,$A6,'Raw Data'!$D:$D,CO$4)
A7: BetMGM | B7: =SUMIFS('Raw Data'!$F:$F,'Raw Data'!$B:$B,$A7,'Raw Data'!$D:$D,B$4) | C7: =SUMIFS('Raw Data'!$F:$F,'Raw Data'!$B:$B,$A7,'Raw Data'!$D:$D,C$4) | D7: =SUMIFS('Raw Data'!$F:$F,'Raw Data'!$B:$B,$A7,'Raw Data'!$D:$D,D$4) | E7: =SUMIFS('Raw Data'!$F:$F,'Raw Data'!$B:$B,$A7,'Raw Data'!$D:$D,E$4) | F7: =SUMIFS('Raw Data'!$F:$F,'Raw Data'!$B:$B,$A7,'Raw Data'!$D:$D,F$4) | G7: =SUMIFS('Raw Data'!$F:$F,'Raw Data'!$B:$B,$A7,'Raw Data'!$D:$D,G$4) | H7: =SUMIFS('Raw Data'!$F:$F,'Raw Data'!$B:$B,$A7,'Raw Data'!$D:$D,H$4) | I7: =SUMIFS('Raw Data'!$F:$F,'Raw Data'!$B:$B,$A7,'Raw Data'!$D:$D,I$4) | ... CO7: =SUMIFS('Raw Data'!$F:$F,'Raw Data'!$B:$B,$A7,'Raw Data'!$D:$D,CO$4)
A8: Fanatics | B8: =SUMIFS('Raw Data'!$F:$F,'Raw Data'!$B:$B,$A8,'Raw Data'!$D:$D,B$4) | C8: =SUMIFS('Raw Data'!$F:$F,'Raw Data'!$B:$B,$A8,'Raw Data'!$D:$D,C$4) | D8: =SUMIFS('Raw Data'!$F:$F,'Raw Data'!$B:$B,$A8,'Raw Data'!$D:$D,D$4) | E8: =SUMIFS('Raw Data'!$F:$F,'Raw Data'!$B:$B,$A8,'Raw Data'!$D:$D,E$4) | F8: =SUMIFS('Raw Data'!$F:$F,'Raw Data'!$B:$B,$A8,'Raw Data'!$D:$D,F$4) | G8: =SUMIFS('Raw Data'!$F:$F,'Raw Data'!$B:$B,$A8,'Raw Data'!$D:$D,G$4) | H8: =SUMIFS('Raw Data'!$F:$F,'Raw Data'!$B:$B,$A8,'Raw Data'!$D:$D,H$4) | I8: =SUMIFS('Raw Data'!$F:$F,'Raw Data'!$B:$B,$A8,'Raw Data'!$D:$D,I$4) | ... CO8: =SUMIFS('Raw Data'!$F:$F,'Raw Data'!$B:$B,$A8,'Raw Data'!$D:$D,CO$4)
A9: Caesars | B9: =SUMIFS('Raw Data'!$F:$F,'Raw Data'!$B:$B,$A9,'Raw Data'!$D:$D,B$4) | C9: =SUMIFS('Raw Data'!$F:$F,'Raw Data'!$B:$B,$A9,'Raw Data'!$D:$D,C$4) | D9: =SUMIFS('Raw Data'!$F:$F,'Raw Data'!$B:$B,$A9,'Raw Data'!$D:$D,D$4) | E9: =SUMIFS('Raw Data'!$F:$F,'Raw Data'!$B:$B,$A9,'Raw Data'!$D:$D,E$4) | F9: =SUMIFS('Raw Data'!$F:$F,'Raw Data'!$B:$B,$A9,'Raw Data'!$D:$D,F$4) | G9: =SUMIFS('Raw Data'!$F:$F,'Raw Data'!$B:$B,$A9,'Raw Data'!$D:$D,G$4) | H9: =SUMIFS('Raw Data'!$F:$F,'Raw Data'!$B:$B,$A9,'Raw Data'!$D:$D,H$4) | I9: =SUMIFS('Raw Data'!$F:$F,'Raw Data'!$B:$B,$A9,'Raw Data'!$D:$D,I$4) | ... CO9: =SUMIFS('Raw Data'!$F:$F,'Raw Data'!$B:$B,$A9,'Raw Data'!$D:$D,CO$4)
A10: ESPN Bet | B10: =SUMIFS('Raw Data'!$F:$F,'Raw Data'!$B:$B,$A10,'Raw Data'!$D:$D,B$4) | C10: =SUMIFS('Raw Data'!$F:$F,'Raw Data'!$B:$B,$A10,'Raw Data'!$D:$D,C$4) | D10: =SUMIFS('Raw Data'!$F:$F,'Raw Data'!$B:$B,$A10,'Raw Data'!$D:$D,D$4) | E10: =SUMIFS('Raw Data'!$F:$F,'Raw Data'!$B:$B,$A10,'Raw Data'!$D:$D,E$4) | F10: =SUMIFS('Raw Data'!$F:$F,'Raw Data'!$B:$B,$A10,'Raw Data'!$D:$D,F$4) | G10: =SUMIFS('Raw Data'!$F:$F,'Raw Data'!$B:$B,$A10,'Raw Data'!$D:$D,G$4) | H10: =SUMIFS('Raw Data'!$F:$F,'Raw Data'!$B:$B,$A10,'Raw Data'!$D:$D,H$4) | I10: =SUMIFS('Raw Data'!$F:$F,'Raw Data'!$B:$B,$A10,'Raw Data'!$D:$D,I$4) | ... CO10: =SUMIFS('Raw Data'!$F:$F,'Raw Data'!$B:$B,$A10,'Raw Data'!$D:$D,CO$4)
A11: Others | B11: =SUMIFS('Raw Data'!$F:$F,'Raw Data'!$B:$B,$A11,'Raw Data'!$D:$D,B$4) | C11: =SUMIFS('Raw Data'!$F:$F,'Raw Data'!$B:$B,$A11,'Raw Data'!$D:$D,C$4) | D11: =SUMIFS('Raw Data'!$F:$F,'Raw Data'!$B:$B,$A11,'Raw Data'!$D:$D,D$4) | E11: =SUMIFS('Raw Data'!$F:$F,'Raw Data'!$B:$B,$A11,'Raw Data'!$D:$D,E$4) | F11: =SUMIFS('Raw Data'!$F:$F,'Raw Data'!$B:$B,$A11,'Raw Data'!$D:$D,F$4) | G11: =SUMIFS('Raw Data'!$F:$F,'Raw Data'!$B:$B,$A11,'Raw Data'!$D:$D,G$4) | H11: =SUMIFS('Raw Data'!$F:$F,'Raw Data'!$B:$B,$A11,'Raw Data'!$D:$D,H$4) | I11: =SUMIFS('Raw Data'!$F:$F,'Raw Data'!$B:$B,$A11,'Raw Data'!$D:$D,I$4) | ... CO11: =SUMIFS('Raw Data'!$F:$F,'Raw Data'!$B:$B,$A11,'Raw Data'!$D:$D,CO$4)
A12: Total | B12: =SUM(B5:B11) | C12: =SUM(C5:C11) | D12: =SUM(D5:D11) | E12: =SUM(E5:E11) | F12: =SUM(F5:F11) | G12: =SUM(G5:G11) | H12: =SUM(H5:H11) | I12: =SUM(I5:I11) | ... CO12: =SUM(CO5:CO11)
A15: GGR ($) — % MARKET SHARE | B15: 43313 | C15: 43344 | D15: 43374 | E15: 43405 | F15: 43435 | G15: 43466 | H15: 43497 | I15: 43525 | J15: 43556 | K15: 43586 | L15: 43617 | M15: 43647 | N15: 43678 | O15: 43709 | P15: 43739 | Q15: 43770 | R15: 43800 | S15: 43831 | T15: 43862 | U15: 43891 | V15: 43922 | W15: 43952 | X15: 43983 | Y15: 44013 | Z15: 44044 | AA15: 44075 | AB15: 44105 | AC15: 44136 | AD15: 44166 | AE15: 44197 | AF15: 44228 | AG15: 44256 | AH15: 44287 | AI15: 44317 | AJ15: 44348 | AK15: 44378 | AL15: 44409 | AM15: 44440 | AN15: 44470 | AO15: 44501 | AP15: 44531 | AQ15: 44562 | AR15: 44593 | AS15: 44621 | AT15: 44652 | AU15: 44682 | AV15: 44713 | AW15: 44743 | AX15: 44774 | AY15: 44805 | AZ15: 44835 | BA15: 44866 | BB15: 44896 | BC15: 44927 | BD15: 44958 | BE15: 44986 | BF15: 45017 | BG15: 45047 | BH15: 45078 | BI15: 45108 | BJ15: 45139 | BK15: 45170 | BL15: 45200 | BM15: 45231 | BN15: 45261 | BO15: 45292 | BP15: 45323 | BQ15: 45352 | BR15: 45383 | BS15: 45413 | BT15: 45444 | BU15: 45474 | BV15: 45505 | BW15: 45536 | BX15: 45566 | BY15: 45597 | BZ15: 45627 | CA15: 45658 | CB15: 45689 | CC15: 45717 | CD15: 45748 | CE15: 45778 | CF15: 45809 | CG15: 45839 | CH15: 45870 | CI15: 45901 | CJ15: 45931 | CK15: 45962 | CL15: 45992 | CM15: 46023 | CN15: 46054 | CO15: 46082
A16: FanDuel | B16: =IFERROR(B5/B12,"") | C16: =IFERROR(C5/C12,"") | D16: =IFERROR(D5/D12,"") | E16: =IFERROR(E5/E12,"") | F16: =IFERROR(F5/F12,"") | G16: =IFERROR(G5/G12,"") | H16: =IFERROR(H5/H12,"") | I16: =IFERROR(I5/I12,"") | ... CO16: =IFERROR(CO5/CO12,"")
A17: DraftKings | B17: =IFERROR(B6/B12,"") | C17: =IFERROR(C6/C12,"") | D17: =IFERROR(D6/D12,"") | E17: =IFERROR(E6/E12,"") | F17: =IFERROR(F6/F12,"") | G17: =IFERROR(G6/G12,"") | H17: =IFERROR(H6/H12,"") | I17: =IFERROR(I6/I12,"") | ... CO17: =IFERROR(CO6/CO12,"")
A18: BetMGM | B18: =IFERROR(B7/B12,"") | C18: =IFERROR(C7/C12,"") | D18: =IFERROR(D7/D12,"") | E18: =IFERROR(E7/E12,"") | F18: =IFERROR(F7/F12,"") | G18: =IFERROR(G7/G12,"") | H18: =IFERROR(H7/H12,"") | I18: =IFERROR(I7/I12,"") | ... CO18: =IFERROR(CO7/CO12,"")
A19: Fanatics | B19: =IFERROR(B8/B12,"") | C19: =IFERROR(C8/C12,"") | D19: =IFERROR(D8/D12,"") | E19: =IFERROR(E8/E12,"") | F19: =IFERROR(F8/F12,"") | G19: =IFERROR(G8/G12,"") | H19: =IFERROR(H8/H12,"") | I19: =IFERROR(I8/I12,"") | ... CO19: =IFERROR(CO8/CO12,"")
A20: Caesars | B20: =IFERROR(B9/B12,"") | C20: =IFERROR(C9/C12,"") | D20: =IFERROR(D9/D12,"") | E20: =IFERROR(E9/E12,"") | F20: =IFERROR(F9/F12,"") | G20: =IFERROR(G9/G12,"") | H20: =IFERROR(H9/H12,"") | I20: =IFERROR(I9/I12,"") | ... CO20: =IFERROR(CO9/CO12,"")
A21: ESPN Bet | B21: =IFERROR(B10/B12,"") | C21: =IFERROR(C10/C12,"") | D21: =IFERROR(D10/D12,"") | E21: =IFERROR(E10/E12,"") | F21: =IFERROR(F10/F12,"") | G21: =IFERROR(G10/G12,"") | H21: =IFERROR(H10/H12,"") | I21: =IFERROR(I10/I12,"") | ... CO21: =IFERROR(CO10/CO12,"")
A22: Others | B22: =IFERROR(B11/B12,"") | C22: =IFERROR(C11/C12,"") | D22: =IFERROR(D11/D12,"") | E22: =IFERROR(E11/E12,"") | F22: =IFERROR(F11/F12,"") | G22: =IFERROR(G11/G12,"") | H22: =IFERROR(H11/H12,"") | I22: =IFERROR(I11/I12,"") | ... CO22: =IFERROR(CO11/CO12,"")
A23: Total | B23: =IFERROR(B12/B12,"") | C23: =IFERROR(C12/C12,"") | D23: =IFERROR(D12/D12,"") | E23: =IFERROR(E12/E12,"") | F23: =IFERROR(F12/F12,"") | G23: =IFERROR(G12/G12,"") | H23: =IFERROR(H12/H12,"") | I23: =IFERROR(I12/I12,"") | ... CO23: =IFERROR(CO12/CO12,"")

Sheet Hold Rate
A1: HOLD RATE — US Online Sports Betting
A2: Hold = GGR / Handle. Linked to Handle and GGR sheets.
A4: HOLD % | B4: 43313 | C4: 43344 | D4: 43374 | E4: 43405 | F4: 43435 | G4: 43466 | H4: 43497 | I4: 43525 | J4: 43556 | K4: 43586 | L4: 43617 | M4: 43647 | N4: 43678 | O4: 43709 | P4: 43739 | Q4: 43770 | R4: 43800 | S4: 43831 | T4: 43862 | U4: 43891 | V4: 43922 | W4: 43952 | X4: 43983 | Y4: 44013 | Z4: 44044 | AA4: 44075 | AB4: 44105 | AC4: 44136 | AD4: 44166 | AE4: 44197 | AF4: 44228 | AG4: 44256 | AH4: 44287 | AI4: 44317 | AJ4: 44348 | AK4: 44378 | AL4: 44409 | AM4: 44440 | AN4: 44470 | AO4: 44501 | AP4: 44531 | AQ4: 44562 | AR4: 44593 | AS4: 44621 | AT4: 44652 | AU4: 44682 | AV4: 44713 | AW4: 44743 | AX4: 44774 | AY4: 44805 | AZ4: 44835 | BA4: 44866 | BB4: 44896 | BC4: 44927 | BD4: 44958 | BE4: 44986 | BF4: 45017 | BG4: 45047 | BH4: 45078 | BI4: 45108 | BJ4: 45139 | BK4: 45170 | BL4: 45200 | BM4: 45231 | BN4: 45261 | BO4: 45292 | BP4: 45323 | BQ4: 45352 | BR4: 45383 | BS4: 45413 | BT4: 45444 | BU4: 45474 | BV4: 45505 | BW4: 45536 | BX4: 45566 | BY4: 45597 | BZ4: 45627 | CA4: 45658 | CB4: 45689 | CC4: 45717 | CD4: 45748 | CE4: 45778 | CF4: 45809 | CG4: 45839 | CH4: 45870 | CI4: 45901 | CJ4: 45931 | CK4: 45962 | CL4: 45992 | CM4: 46023 | CN4: 46054 | CO4: 46082
A5: FanDuel | B5: =IFERROR(GGR!B5/Handle!B5,"") | C5: =IFERROR(GGR!C5/Handle!C5,"") | D5: =IFERROR(GGR!D5/Handle!D5,"") | E5: =IFERROR(GGR!E5/Handle!E5,"") | F5: =IFERROR(GGR!F5/Handle!F5,"") | G5: =IFERROR(GGR!G5/Handle!G5,"") | H5: =IFERROR(GGR!H5/Handle!H5,"") | I5: =IFERROR(GGR!I5/Handle!I5,"") | ... CO5: =IFERROR(GGR!CO5/Handle!CO5,"")
A6: DraftKings | B6: =IFERROR(GGR!B6/Handle!B6,"") | C6: =IFERROR(GGR!C6/Handle!C6,"") | D6: =IFERROR(GGR!D6/Handle!D6,"") | E6: =IFERROR(GGR!E6/Handle!E6,"") | F6: =IFERROR(GGR!F6/Handle!F6,"") | G6: =IFERROR(GGR!G6/Handle!G6,"") | H6: =IFERROR(GGR!H6/Handle!H6,"") | I6: =IFERROR(GGR!I6/Handle!I6,"") | ... CO6: =IFERROR(GGR!CO6/Handle!CO6,"")
A7: BetMGM | B7: =IFERROR(GGR!B7/Handle!B7,"") | C7: =IFERROR(GGR!C7/Handle!C7,"") | D7: =IFERROR(GGR!D7/Handle!D7,"") | E7: =IFERROR(GGR!E7/Handle!E7,"") | F7: =IFERROR(GGR!F7/Handle!F7,"") | G7: =IFERROR(GGR!G7/Handle!G7,"") | H7: =IFERROR(GGR!H7/Handle!H7,"") | I7: =IFERROR(GGR!I7/Handle!I7,"") | ... CO7: =IFERROR(GGR!CO7/Handle!CO7,"")
A8: Fanatics | B8: =IFERROR(GGR!B8/Handle!B8,"") | C8: =IFERROR(GGR!C8/Handle!C8,"") | D8: =IFERROR(GGR!D8/Handle!D8,"") | E8: =IFERROR(GGR!E8/Handle!E8,"") | F8: =IFERROR(GGR!F8/Handle!F8,"") | G8: =IFERROR(GGR!G8/Handle!G8,"") | H8: =IFERROR(GGR!H8/Handle!H8,"") | I8: =IFERROR(GGR!I8/Handle!I8,"") | ... CO8: =IFERROR(GGR!CO8/Handle!CO8,"")
A9: Caesars | B9: =IFERROR(GGR!B9/Handle!B9,"") | C9: =IFERROR(GGR!C9/Handle!C9,"") | D9: =IFERROR(GGR!D9/Handle!D9,"") | E9: =IFERROR(GGR!E9/Handle!E9,"") | F9: =IFERROR(GGR!F9/Handle!F9,"") | G9: =IFERROR(GGR!G9/Handle!G9,"") | H9: =IFERROR(GGR!H9/Handle!H9,"") | I9: =IFERROR(GGR!I9/Handle!I9,"") | ... CO9: =IFERROR(GGR!CO9/Handle!CO9,"")
A10: ESPN Bet | B10: =IFERROR(GGR!B10/Handle!B10,"") | C10: =IFERROR(GGR!C10/Handle!C10,"") | D10: =IFERROR(GGR!D10/Handle!D10,"") | E10: =IFERROR(GGR!E10/Handle!E10,"") | F10: =IFERROR(GGR!F10/Handle!F10,"") | G10: =IFERROR(GGR!G10/Handle!G10,"") | H10: =IFERROR(GGR!H10/Handle!H10,"") | I10: =IFERROR(GGR!I10/Handle!I10,"") | ... CO10: =IFERROR(GGR!CO10/Handle!CO10,"")
A11: Others | B11: =IFERROR(GGR!B11/Handle!B11,"") | C11: =IFERROR(GGR!C11/Handle!C11,"") | D11: =IFERROR(GGR!D11/Handle!D11,"") | E11: =IFERROR(GGR!E11/Handle!E11,"") | F11: =IFERROR(GGR!F11/Handle!F11,"") | G11: =IFERROR(GGR!G11/Handle!G11,"") | H11: =IFERROR(GGR!H11/Handle!H11,"") | I11: =IFERROR(GGR!I11/Handle!I11,"") | ... CO11: =IFERROR(GGR!CO11/Handle!CO11,"")
A12: Total | B12: =IFERROR(GGR!B12/Handle!B12,"") | C12: =IFERROR(GGR!C12/Handle!C12,"") | D12: =IFERROR(GGR!D12/Handle!D12,"") | E12: =IFERROR(GGR!E12/Handle!E12,"") | F12: =IFERROR(GGR!F12/Handle!F12,"") | G12: =IFERROR(GGR!G12/Handle!G12,"") | H12: =IFERROR(GGR!H12/Handle!H12,"") | I12: =IFERROR(GGR!I12/Handle!I12,"") | ... CO12: =IFERROR(GGR!CO12/Handle!CO12,"")

Sheet Handle Growth YoY
A1: HANDLE Y/Y GROWTH — US Online Sports Betting
A2: Y/Y growth = current month / same month prior year − 1. Linked to Handle sheet. Cells before the first available prior-year month are blank.
A4: HANDLE Y/Y GROWTH | B4: 43313 | C4: 43344 | D4: 43374 | E4: 43405 | F4: 43435 | G4: 43466 | H4: 43497 | I4: 43525 | J4: 43556 | K4: 43586 | L4: 43617 | M4: 43647 | N4: 43678 | O4: 43709 | P4: 43739 | Q4: 43770 | R4: 43800 | S4: 43831 | T4: 43862 | U4: 43891 | V4: 43922 | W4: 43952 | X4: 43983 | Y4: 44013 | Z4: 44044 | AA4: 44075 | AB4: 44105 | AC4: 44136 | AD4: 44166 | AE4: 44197 | AF4: 44228 | AG4: 44256 | AH4: 44287 | AI4: 44317 | AJ4: 44348 | AK4: 44378 | AL4: 44409 | AM4: 44440 | AN4: 44470 | AO4: 44501 | AP4: 44531 | AQ4: 44562 | AR4: 44593 | AS4: 44621 | AT4: 44652 | AU4: 44682 | AV4: 44713 | AW4: 44743 | AX4: 44774 | AY4: 44805 | AZ4: 44835 | BA4: 44866 | BB4: 44896 | BC4: 44927 | BD4: 44958 | BE4: 44986 | BF4: 45017 | BG4: 45047 | BH4: 45078 | BI4: 45108 | BJ4: 45139 | BK4: 45170 | BL4: 45200 | BM4: 45231 | BN4: 45261 | BO4: 45292 | BP4: 45323 | BQ4: 45352 | BR4: 45383 | BS4: 45413 | BT4: 45444 | BU4: 45474 | BV4: 45505 | BW4: 45536 | BX4: 45566 | BY4: 45597 | BZ4: 45627 | CA4: 45658 | CB4: 45689 | CC4: 45717 | CD4: 45748 | CE4: 45778 | CF4: 45809 | CG4: 45839 | CH4: 45870 | CI4: 45901 | CJ4: 45931 | CK4: 45962 | CL4: 45992 | CM4: 46023 | CN4: 46054 | CO4: 46082
A5: FanDuel | B5: =IFERROR(Handle!B5/INDEX(Handle!5:5,MATCH(EDATE(B$4,-12),Handle!$4:$4,0))-1,"") | C5: =IFERROR(Handle!C5/INDEX(Handle!5:5,MATCH(EDATE(C$4,-12),Handle!$4:$4,0))-1,"") | D5: =IFERROR(Handle!D5/INDEX(Handle!5:5,MATCH(EDATE(D$4,-12),Handle!$4:$4,0))-1,"") | E5: =IFERROR(Handle!E5/INDEX(Handle!5:5,MATCH(EDATE(E$4,-12),Handle!$4:$4,0))-1,"") | F5: =IFERROR(Handle!F5/INDEX(Handle!5:5,MATCH(EDATE(F$4,-12),Handle!$4:$4,0))-1,"") | G5: =IFERROR(Handle!G5/INDEX(Handle!5:5,MATCH(EDATE(G$4,-12),Handle!$4:$4,0))-1,"") | H5: =IFERROR(Handle!H5/INDEX(Handle!5:5,MATCH(EDATE(H$4,-12),Handle!$4:$4,0))-1,"") | I5: =IFERROR(Handle!I5/INDEX(Handle!5:5,MATCH(EDATE(I$4,-12),Handle!$4:$4,0))-1,"") | ... CO5: =IFERROR(Handle!CO5/INDEX(Handle!5:5,MATCH(EDATE(CO$4,-12),Handle!$4:$4,0))-1,"")
A6: DraftKings | B6: =IFERROR(Handle!B6/INDEX(Handle!6:6,MATCH(EDATE(B$4,-12),Handle!$4:$4,0))-1,"") | C6: =IFERROR(Handle!C6/INDEX(Handle!6:6,MATCH(EDATE(C$4,-12),Handle!$4:$4,0))-1,"") | D6: =IFERROR(Handle!D6/INDEX(Handle!6:6,MATCH(EDATE(D$4,-12),Handle!$4:$4,0))-1,"") | E6: =IFERROR(Handle!E6/INDEX(Handle!6:6,MATCH(EDATE(E$4,-12),Handle!$4:$4,0))-1,"") | F6: =IFERROR(Handle!F6/INDEX(Handle!6:6,MATCH(EDATE(F$4,-12),Handle!$4:$4,0))-1,"") | G6: =IFERROR(Handle!G6/INDEX(Handle!6:6,MATCH(EDATE(G$4,-12),Handle!$4:$4,0))-1,"") | H6: =IFERROR(Handle!H6/INDEX(Handle!6:6,MATCH(EDATE(H$4,-12),Handle!$4:$4,0))-1,"") | I6: =IFERROR(Handle!I6/INDEX(Handle!6:6,MATCH(EDATE(I$4,-12),Handle!$4:$4,0))-1,"") | ... CO6: =IFERROR(Handle!CO6/INDEX(Handle!6:6,MATCH(EDATE(CO$4,-12),Handle!$4:$4,0))-1,"")
A7: BetMGM | B7: =IFERROR(Handle!B7/INDEX(Handle!7:7,MATCH(EDATE(B$4,-12),Handle!$4:$4,0))-1,"") | C7: =IFERROR(Handle!C7/INDEX(Handle!7:7,MATCH(EDATE(C$4,-12),Handle!$4:$4,0))-1,"") | D7: =IFERROR(Handle!D7/INDEX(Handle!7:7,MATCH(EDATE(D$4,-12),Handle!$4:$4,0))-1,"") | E7: =IFERROR(Handle!E7/INDEX(Handle!7:7,MATCH(EDATE(E$4,-12),Handle!$4:$4,0))-1,"") | F7: =IFERROR(Handle!F7/INDEX(Handle!7:7,MATCH(EDATE(F$4,-12),Handle!$4:$4,0))-1,"") | G7: =IFERROR(Handle!G7/INDEX(Handle!7:7,MATCH(EDATE(G$4,-12),Handle!$4:$4,0))-1,"") | H7: =IFERROR(Handle!H7/INDEX(Handle!7:7,MATCH(EDATE(H$4,-12),Handle!$4:$4,0))-1,"") | I7: =IFERROR(Handle!I7/INDEX(Handle!7:7,MATCH(EDATE(I$4,-12),Handle!$4:$4,0))-1,"") | ... CO7: =IFERROR(Handle!CO7/INDEX(Handle!7:7,MATCH(EDATE(CO$4,-12),Handle!$4:$4,0))-1,"")
A8: Fanatics | B8: =IFERROR(Handle!B8/INDEX(Handle!8:8,MATCH(EDATE(B$4,-12),Handle!$4:$4,0))-1,"") | C8: =IFERROR(Handle!C8/INDEX(Handle!8:8,MATCH(EDATE(C$4,-12),Handle!$4:$4,0))-1,"") | D8: =IFERROR(Handle!D8/INDEX(Handle!8:8,MATCH(EDATE(D$4,-12),Handle!$4:$4,0))-1,"") | E8: =IFERROR(Handle!E8/INDEX(Handle!8:8,MATCH(EDATE(E$4,-12),Handle!$4:$4,0))-1,"") | F8: =IFERROR(Handle!F8/INDEX(Handle!8:8,MATCH(EDATE(F$4,-12),Handle!$4:$4,0))-1,"") | G8: =IFERROR(Handle!G8/INDEX(Handle!8:8,MATCH(EDATE(G$4,-12),Handle!$4:$4,0))-1,"") | H8: =IFERROR(Handle!H8/INDEX(Handle!8:8,MATCH(EDATE(H$4,-12),Handle!$4:$4,0))-1,"") | I8: =IFERROR(Handle!I8/INDEX(Handle!8:8,MATCH(EDATE(I$4,-12),Handle!$4:$4,0))-1,"") | ... CO8: =IFERROR(Handle!CO8/INDEX(Handle!8:8,MATCH(EDATE(CO$4,-12),Handle!$4:$4,0))-1,"")
A9: Caesars | B9: =IFERROR(Handle!B9/INDEX(Handle!9:9,MATCH(EDATE(B$4,-12),Handle!$4:$4,0))-1,"") | C9: =IFERROR(Handle!C9/INDEX(Handle!9:9,MATCH(EDATE(C$4,-12),Handle!$4:$4,0))-1,"") | D9: =IFERROR(Handle!D9/INDEX(Handle!9:9,MATCH(EDATE(D$4,-12),Handle!$4:$4,0))-1,"") | E9: =IFERROR(Handle!E9/INDEX(Handle!9:9,MATCH(EDATE(E$4,-12),Handle!$4:$4,0))-1,"") | F9: =IFERROR(Handle!F9/INDEX(Handle!9:9,MATCH(EDATE(F$4,-12),Handle!$4:$4,0))-1,"") | G9: =IFERROR(Handle!G9/INDEX(Handle!9:9,MATCH(EDATE(G$4,-12),Handle!$4:$4,0))-1,"") | H9: =IFERROR(Handle!H9/INDEX(Handle!9:9,MATCH(EDATE(H$4,-12),Handle!$4:$4,0))-1,"") | I9: =IFERROR(Handle!I9/INDEX(Handle!9:9,MATCH(EDATE(I$4,-12),Handle!$4:$4,0))-1,"") | ... CO9: =IFERROR(Handle!CO9/INDEX(Handle!9:9,MATCH(EDATE(CO$4,-12),Handle!$4:$4,0))-1,"")
A10: ESPN Bet | B10: =IFERROR(Handle!B10/INDEX(Handle!10:10,MATCH(EDATE(B$4,-12),Handle!$4:$4,0))-1,"") | C10: =IFERROR(Handle!C10/INDEX(Handle!10:10,MATCH(EDATE(C$4,-12),Handle!$4:$4,0))-1,"") | D10: =IFERROR(Handle!D10/INDEX(Handle!10:10,MATCH(EDATE(D$4,-12),Handle!$4:$4,0))-1,"") | E10: =IFERROR(Handle!E10/INDEX(Handle!10:10,MATCH(EDATE(E$4,-12),Handle!$4:$4,0))-1,"") | F10: =IFERROR(Handle!F10/INDEX(Handle!10:10,MATCH(EDATE(F$4,-12),Handle!$4:$4,0))-1,"") | G10: =IFERROR(Handle!G10/INDEX(Handle!10:10,MATCH(EDATE(G$4,-12),Handle!$4:$4,0))-1,"") | H10: =IFERROR(Handle!H10/INDEX(Handle!10:10,MATCH(EDATE(H$4,-12),Handle!$4:$4,0))-1,"") | I10: =IFERROR(Handle!I10/INDEX(Handle!10:10,MATCH(EDATE(I$4,-12),Handle!$4:$4,0))-1,"") | ... CO10: =IFERROR(Handle!CO10/INDEX(Handle!10:10,MATCH(EDATE(CO$4,-12),Handle!$4:$4,0))-1,"")
A11: Others | B11: =IFERROR(Handle!B11/INDEX(Handle!11:11,MATCH(EDATE(B$4,-12),Handle!$4:$4,0))-1,"") | C11: =IFERROR(Handle!C11/INDEX(Handle!11:11,MATCH(EDATE(C$4,-12),Handle!$4:$4,0))-1,"") | D11: =IFERROR(Handle!D11/INDEX(Handle!11:11,MATCH(EDATE(D$4,-12),Handle!$4:$4,0))-1,"") | E11: =IFERROR(Handle!E11/INDEX(Handle!11:11,MATCH(EDATE(E$4,-12),Handle!$4:$4,0))-1,"") | F11: =IFERROR(Handle!F11/INDEX(Handle!11:11,MATCH(EDATE(F$4,-12),Handle!$4:$4,0))-1,"") | G11: =IFERROR(Handle!G11/INDEX(Handle!11:11,MATCH(EDATE(G$4,-12),Handle!$4:$4,0))-1,"") | H11: =IFERROR(Handle!H11/INDEX(Handle!11:11,MATCH(EDATE(H$4,-12),Handle!$4:$4,0))-1,"") | I11: =IFERROR(Handle!I11/INDEX(Handle!11:11,MATCH(EDATE(I$4,-12),Handle!$4:$4,0))-1,"") | ... CO11: =IFERROR(Handle!CO11/INDEX(Handle!11:11,MATCH(EDATE(CO$4,-12),Handle!$4:$4,0))-1,"")
A12: Total | B12: =IFERROR(Handle!B12/INDEX(Handle!12:12,MATCH(EDATE(B$4,-12),Handle!$4:$4,0))-1,"") | C12: =IFERROR(Handle!C12/INDEX(Handle!12:12,MATCH(EDATE(C$4,-12),Handle!$4:$4,0))-1,"") | D12: =IFERROR(Handle!D12/INDEX(Handle!12:12,MATCH(EDATE(D$4,-12),Handle!$4:$4,0))-1,"") | E12: =IFERROR(Handle!E12/INDEX(Handle!12:12,MATCH(EDATE(E$4,-12),Handle!$4:$4,0))-1,"") | F12: =IFERROR(Handle!F12/INDEX(Handle!12:12,MATCH(EDATE(F$4,-12),Handle!$4:$4,0))-1,"") | G12: =IFERROR(Handle!G12/INDEX(Handle!12:12,MATCH(EDATE(G$4,-12),Handle!$4:$4,0))-1,"") | H12: =IFERROR(Handle!H12/INDEX(Handle!12:12,MATCH(EDATE(H$4,-12),Handle!$4:$4,0))-1,"") | I12: =IFERROR(Handle!I12/INDEX(Handle!12:12,MATCH(EDATE(I$4,-12),Handle!$4:$4,0))-1,"") | ... CO12: =IFERROR(Handle!CO12/INDEX(Handle!12:12,MATCH(EDATE(CO$4,-12),Handle!$4:$4,0))-1,"")

Sheet GGR Growth YoY
A1: GGR Y/Y GROWTH — US Online Sports Betting
A2: Y/Y growth = current month / same month prior year − 1. Linked to GGR sheet. Cells before the first available prior-year month are blank.
A4: GGR Y/Y GROWTH | B4: 43313 | C4: 43344 | D4: 43374 | E4: 43405 | F4: 43435 | G4: 43466 | H4: 43497 | I4: 43525 | J4: 43556 | K4: 43586 | L4: 43617 | M4: 43647 | N4: 43678 | O4: 43709 | P4: 43739 | Q4: 43770 | R4: 43800 | S4: 43831 | T4: 43862 | U4: 43891 | V4: 43922 | W4: 43952 | X4: 43983 | Y4: 44013 | Z4: 44044 | AA4: 44075 | AB4: 44105 | AC4: 44136 | AD4: 44166 | AE4: 44197 | AF4: 44228 | AG4: 44256 | AH4: 44287 | AI4: 44317 | AJ4: 44348 | AK4: 44378 | AL4: 44409 | AM4: 44440 | AN4: 44470 | AO4: 44501 | AP4: 44531 | AQ4: 44562 | AR4: 44593 | AS4: 44621 | AT4: 44652 | AU4: 44682 | AV4: 44713 | AW4: 44743 | AX4: 44774 | AY4: 44805 | AZ4: 44835 | BA4: 44866 | BB4: 44896 | BC4: 44927 | BD4: 44958 | BE4: 44986 | BF4: 45017 | BG4: 45047 | BH4: 45078 | BI4: 45108 | BJ4: 45139 | BK4: 45170 | BL4: 45200 | BM4: 45231 | BN4: 45261 | BO4: 45292 | BP4: 45323 | BQ4: 45352 | BR4: 45383 | BS4: 45413 | BT4: 45444 | BU4: 45474 | BV4: 45505 | BW4: 45536 | BX4: 45566 | BY4: 45597 | BZ4: 45627 | CA4: 45658 | CB4: 45689 | CC4: 45717 | CD4: 45748 | CE4: 45778 | CF4: 45809 | CG4: 45839 | CH4: 45870 | CI4: 45901 | CJ4: 45931 | CK4: 45962 | CL4: 45992 | CM4: 46023 | CN4: 46054 | CO4: 46082
A5: FanDuel | B5: =IFERROR(GGR!B5/INDEX(GGR!5:5,MATCH(EDATE(B$4,-12),GGR!$4:$4,0))-1,"") | C5: =IFERROR(GGR!C5/INDEX(GGR!5:5,MATCH(EDATE(C$4,-12),GGR!$4:$4,0))-1,"") | D5: =IFERROR(GGR!D5/INDEX(GGR!5:5,MATCH(EDATE(D$4,-12),GGR!$4:$4,0))-1,"") | E5: =IFERROR(GGR!E5/INDEX(GGR!5:5,MATCH(EDATE(E$4,-12),GGR!$4:$4,0))-1,"") | F5: =IFERROR(GGR!F5/INDEX(GGR!5:5,MATCH(EDATE(F$4,-12),GGR!$4:$4,0))-1,"") | G5: =IFERROR(GGR!G5/INDEX(GGR!5:5,MATCH(EDATE(G$4,-12),GGR!$4:$4,0))-1,"") | H5: =IFERROR(GGR!H5/INDEX(GGR!5:5,MATCH(EDATE(H$4,-12),GGR!$4:$4,0))-1,"") | I5: =IFERROR(GGR!I5/INDEX(GGR!5:5,MATCH(EDATE(I$4,-12),GGR!$4:$4,0))-1,"") | ... CO5: =IFERROR(GGR!CO5/INDEX(GGR!5:5,MATCH(EDATE(CO$4,-12),GGR!$4:$4,0))-1,"")
A6: DraftKings | B6: =IFERROR(GGR!B6/INDEX(GGR!6:6,MATCH(EDATE(B$4,-12),GGR!$4:$4,0))-1,"") | C6: =IFERROR(GGR!C6/INDEX(GGR!6:6,MATCH(EDATE(C$4,-12),GGR!$4:$4,0))-1,"") | D6: =IFERROR(GGR!D6/INDEX(GGR!6:6,MATCH(EDATE(D$4,-12),GGR!$4:$4,0))-1,"") | E6: =IFERROR(GGR!E6/INDEX(GGR!6:6,MATCH(EDATE(E$4,-12),GGR!$4:$4,0))-1,"") | F6: =IFERROR(GGR!F6/INDEX(GGR!6:6,MATCH(EDATE(F$4,-12),GGR!$4:$4,0))-1,"") | G6: =IFERROR(GGR!G6/INDEX(GGR!6:6,MATCH(EDATE(G$4,-12),GGR!$4:$4,0))-1,"") | H6: =IFERROR(GGR!H6/INDEX(GGR!6:6,MATCH(EDATE(H$4,-12),GGR!$4:$4,0))-1,"") | I6: =IFERROR(GGR!I6/INDEX(GGR!6:6,MATCH(EDATE(I$4,-12),GGR!$4:$4,0))-1,"") | ... CO6: =IFERROR(GGR!CO6/INDEX(GGR!6:6,MATCH(EDATE(CO$4,-12),GGR!$4:$4,0))-1,"")
A7: BetMGM | B7: =IFERROR(GGR!B7/INDEX(GGR!7:7,MATCH(EDATE(B$4,-12),GGR!$4:$4,0))-1,"") | C7: =IFERROR(GGR!C7/INDEX(GGR!7:7,MATCH(EDATE(C$4,-12),GGR!$4:$4,0))-1,"") | D7: =IFERROR(GGR!D7/INDEX(GGR!7:7,MATCH(EDATE(D$4,-12),GGR!$4:$4,0))-1,"") | E7: =IFERROR(GGR!E7/INDEX(GGR!7:7,MATCH(EDATE(E$4,-12),GGR!$4:$4,0))-1,"") | F7: =IFERROR(GGR!F7/INDEX(GGR!7:7,MATCH(EDATE(F$4,-12),GGR!$4:$4,0))-1,"") | G7: =IFERROR(GGR!G7/INDEX(GGR!7:7,MATCH(EDATE(G$4,-12),GGR!$4:$4,0))-1,"") | H7: =IFERROR(GGR!H7/INDEX(GGR!7:7,MATCH(EDATE(H$4,-12),GGR!$4:$4,0))-1,"") | I7: =IFERROR(GGR!I7/INDEX(GGR!7:7,MATCH(EDATE(I$4,-12),GGR!$4:$4,0))-1,"") | ... CO7: =IFERROR(GGR!CO7/INDEX(GGR!7:7,MATCH(EDATE(CO$4,-12),GGR!$4:$4,0))-1,"")
A8: Fanatics | B8: =IFERROR(GGR!B8/INDEX(GGR!8:8,MATCH(EDATE(B$4,-12),GGR!$4:$4,0))-1,"") | C8: =IFERROR(GGR!C8/INDEX(GGR!8:8,MATCH(EDATE(C$4,-12),GGR!$4:$4,0))-1,"") | D8: =IFERROR(GGR!D8/INDEX(GGR!8:8,MATCH(EDATE(D$4,-12),GGR!$4:$4,0))-1,"") | E8: =IFERROR(GGR!E8/INDEX(GGR!8:8,MATCH(EDATE(E$4,-12),GGR!$4:$4,0))-1,"") | F8: =IFERROR(GGR!F8/INDEX(GGR!8:8,MATCH(EDATE(F$4,-12),GGR!$4:$4,0))-1,"") | G8: =IFERROR(GGR!G8/INDEX(GGR!8:8,MATCH(EDATE(G$4,-12),GGR!$4:$4,0))-1,"") | H8: =IFERROR(GGR!H8/INDEX(GGR!8:8,MATCH(EDATE(H$4,-12),GGR!$4:$4,0))-1,"") | I8: =IFERROR(GGR!I8/INDEX(GGR!8:8,MATCH(EDATE(I$4,-12),GGR!$4:$4,0))-1,"") | ... CO8: =IFERROR(GGR!CO8/INDEX(GGR!8:8,MATCH(EDATE(CO$4,-12),GGR!$4:$4,0))-1,"")
A9: Caesars | B9: =IFERROR(GGR!B9/INDEX(GGR!9:9,MATCH(EDATE(B$4,-12),GGR!$4:$4,0))-1,"") | C9: =IFERROR(GGR!C9/INDEX(GGR!9:9,MATCH(EDATE(C$4,-12),GGR!$4:$4,0))-1,"") | D9: =IFERROR(GGR!D9/INDEX(GGR!9:9,MATCH(EDATE(D$4,-12),GGR!$4:$4,0))-1,"") | E9: =IFERROR(GGR!E9/INDEX(GGR!9:9,MATCH(EDATE(E$4,-12),GGR!$4:$4,0))-1,"") | F9: =IFERROR(GGR!F9/INDEX(GGR!9:9,MATCH(EDATE(F$4,-12),GGR!$4:$4,0))-1,"") | G9: =IFERROR(GGR!G9/INDEX(GGR!9:9,MATCH(EDATE(G$4,-12),GGR!$4:$4,0))-1,"") | H9: =IFERROR(GGR!H9/INDEX(GGR!9:9,MATCH(EDATE(H$4,-12),GGR!$4:$4,0))-1,"") | I9: =IFERROR(GGR!I9/INDEX(GGR!9:9,MATCH(EDATE(I$4,-12),GGR!$4:$4,0))-1,"") | ... CO9: =IFERROR(GGR!CO9/INDEX(GGR!9:9,MATCH(EDATE(CO$4,-12),GGR!$4:$4,0))-1,"")
A10: ESPN Bet | B10: =IFERROR(GGR!B10/INDEX(GGR!10:10,MATCH(EDATE(B$4,-12),GGR!$4:$4,0))-1,"") | C10: =IFERROR(GGR!C10/INDEX(GGR!10:10,MATCH(EDATE(C$4,-12),GGR!$4:$4,0))-1,"") | D10: =IFERROR(GGR!D10/INDEX(GGR!10:10,MATCH(EDATE(D$4,-12),GGR!$4:$4,0))-1,"") | E10: =IFERROR(GGR!E10/INDEX(GGR!10:10,MATCH(EDATE(E$4,-12),GGR!$4:$4,0))-1,"") | F10: =IFERROR(GGR!F10/INDEX(GGR!10:10,MATCH(EDATE(F$4,-12),GGR!$4:$4,0))-1,"") | G10: =IFERROR(GGR!G10/INDEX(GGR!10:10,MATCH(EDATE(G$4,-12),GGR!$4:$4,0))-1,"") | H10: =IFERROR(GGR!H10/INDEX(GGR!10:10,MATCH(EDATE(H$4,-12),GGR!$4:$4,0))-1,"") | I10: =IFERROR(GGR!I10/INDEX(GGR!10:10,MATCH(EDATE(I$4,-12),GGR!$4:$4,0))-1,"") | ... CO10: =IFERROR(GGR!CO10/INDEX(GGR!10:10,MATCH(EDATE(CO$4,-12),GGR!$4:$4,0))-1,"")
A11: Others | B11: =IFERROR(GGR!B11/INDEX(GGR!11:11,MATCH(EDATE(B$4,-12),GGR!$4:$4,0))-1,"") | C11: =IFERROR(GGR!C11/INDEX(GGR!11:11,MATCH(EDATE(C$4,-12),GGR!$4:$4,0))-1,"") | D11: =IFERROR(GGR!D11/INDEX(GGR!11:11,MATCH(EDATE(D$4,-12),GGR!$4:$4,0))-1,"") | E11: =IFERROR(GGR!E11/INDEX(GGR!11:11,MATCH(EDATE(E$4,-12),GGR!$4:$4,0))-1,"") | F11: =IFERROR(GGR!F11/INDEX(GGR!11:11,MATCH(EDATE(F$4,-12),GGR!$4:$4,0))-1,"") | G11: =IFERROR(GGR!G11/INDEX(GGR!11:11,MATCH(EDATE(G$4,-12),GGR!$4:$4,0))-1,"") | H11: =IFERROR(GGR!H11/INDEX(GGR!11:11,MATCH(EDATE(H$4,-12),GGR!$4:$4,0))-1,"") | I11: =IFERROR(GGR!I11/INDEX(GGR!11:11,MATCH(EDATE(I$4,-12),GGR!$4:$4,0))-1,"") | ... CO11: =IFERROR(GGR!CO11/INDEX(GGR!11:11,MATCH(EDATE(CO$4,-12),GGR!$4:$4,0))-1,"")
A12: Total | B12: =IFERROR(GGR!B12/INDEX(GGR!12:12,MATCH(EDATE(B$4,-12),GGR!$4:$4,0))-1,"") | C12: =IFERROR(GGR!C12/INDEX(GGR!12:12,MATCH(EDATE(C$4,-12),GGR!$4:$4,0))-1,"") | D12: =IFERROR(GGR!D12/INDEX(GGR!12:12,MATCH(EDATE(D$4,-12),GGR!$4:$4,0))-1,"") | E12: =IFERROR(GGR!E12/INDEX(GGR!12:12,MATCH(EDATE(E$4,-12),GGR!$4:$4,0))-1,"") | F12: =IFERROR(GGR!F12/INDEX(GGR!12:12,MATCH(EDATE(F$4,-12),GGR!$4:$4,0))-1,"") | G12: =IFERROR(GGR!G12/INDEX(GGR!12:12,MATCH(EDATE(G$4,-12),GGR!$4:$4,0))-1,"") | H12: =IFERROR(GGR!H12/INDEX(GGR!12:12,MATCH(EDATE(H$4,-12),GGR!$4:$4,0))-1,"") | I12: =IFERROR(GGR!I12/INDEX(GGR!12:12,MATCH(EDATE(I$4,-12),GGR!$4:$4,0))-1,"") | ... CO12: =IFERROR(GGR!CO12/INDEX(GGR!12:12,MATCH(EDATE(CO$4,-12),GGR!$4:$4,0))-1,"")

Sheet Raw Data
A1: State | B1: Bucket | C1: Parent Company | D1: Month | E1: Handle ($) | F1: GGR ($) | G1: Hold %
A2: AZ | B2: BetMGM | C2: Entain/MGM Resorts | D2: 44440 | E2: 58918283 | F2: 10726931 | G2: 0.18206456
A3: AZ | B3: BetMGM | C3: Entain/MGM Resorts | D3: 44470 | E3: 92083455 | F3: 7857407.2 | G3: 0.085329196
A4: AZ | B4: BetMGM | C4: Entain/MGM Resorts | D4: 44501 | E4: 93159932 | F4: 9745423.5 | G4: 0.1046096
A5: AZ | B5: BetMGM | C5: Entain/MGM Resorts | D5: 44531 | E5: 1.0376419e+08 | F5: 9060341 | G5: 0.087316644
A6: AZ | B6: BetMGM | C6: Entain/MGM Resorts | D6: 44562 | E6: 1.2004651e+08 | F6: 10971841 | G6: 0.09139659
A7: AZ | B7: BetMGM | C7: Entain/MGM Resorts | D7: 44593 | E7: 99840970 | F7: 8805081 | G7: 0.08819106
A8: AZ | B8: BetMGM | C8: Entain/MGM Resorts | D8: 44621 | E8: 1.337475e+08 | F8: 10661742 | G8: 0.07971545
A9: AZ | B9: BetMGM | C9: Entain/MGM Resorts | D9: 44652 | E9: 1.006077e+08 | F9: 7989180.3 | G9: 0.079409231
A10: AZ | B10: BetMGM | C10: Entain/MGM Resorts | D10: 44682 | E10: 84195599 | F10: 10193786 | G10: 0.12107267
A11: AZ | B11: BetMGM | C11: Entain/MGM Resorts | D11: 44713 | E11: 59700717 | F11: 5393629 | G11: 0.090344459
A12: AZ | B12: BetMGM | C12: Entain/MGM Resorts | D12: 44743 | E12: 53579719 | F12: 5703089.4 | G12: 0.1064412
A13: AZ | B13: BetMGM | C13: Entain/MGM Resorts | D13: 44774 | E13: 58205052 | F13: 7383066 | G13: 0.12684579
... A734: IA | B734: BetMGM | C734: Entain/MGM Resorts | D734: 45474 | E734: 479309.88 | F734: 64969.26 | G734: 0.13554751
A735: IA | B735: BetMGM | C735: Entain/MGM Resorts | D735: 45505 | E735: 0 | F735: 0
A736: IA | B736: BetMGM | C736: Entain/MGM Resorts | D736: 45536 | E736: 63004.14 | F736: 6724.24 | G736: 0.10672695
A737: IA | B737: BetMGM | C737: Entain/MGM Resorts | D737: 45566 | E737: 0 | F737: 0
A738: IA | B738: BetMGM | C738: Entain/MGM Resorts | D738: 45597 | E738: 0 | F738: 0
A739: IA | B739: BetMGM | C739: Entain/MGM Resorts | D739: 45627 | E739: 0 | F739: 0
A740: IA | B740: BetMGM | C740: Entain/MGM Resorts | D740: 45658 | E740: 0 | F740: 0
A741: IA | B741: BetMGM | C741: Entain/MGM Resorts | D741: 45689 | E741: 0 | F741: 0
A742: IA | B742: BetMGM | C742: Entain/MGM Resorts | D742: 45717 | E742: 0 | F742: 0
A743: IA | B743: BetMGM | C743: Entain/MGM Resorts | D743: 45748 | E743: 0 | F743: 0
A744: IA | B744: BetMGM | C744: Entain/MGM Resorts | D744: 45778 | E744: 14433333 | F744: 1177777.8 | G744: 0.081601233
A745: IA | B745: BetMGM | C745: Entain/MGM Resorts | D745: 45809 | E745: 17954441 | F745: 1196904 | G745: 0.066663396
A746: IA | B746: BetMGM | C746: Entain/MGM Resorts | D746: 45839 | E746: 11443112 | F746: 1450385 | G746: 0.12674743
A747: IA | B747: BetMGM | C747: Entain/MGM Resorts | D747: 45870 | E747: 14413600 | F747: 1679547.9 | G747: 0.11652522
A748: IA | B748: BetMGM | C748: Entain/MGM Resorts | D748: 45901 | E748: 19651974 | F748: 1302465.2 | G748: 0.066276558
A749: IA | B749: BetMGM | C749: Entain/MGM Resorts | D749: 45931 | E749: 17380192 | F749: 2070216.9 | G749: 0.11911358
A750: IA | B750: BetMGM | C750: Entain/MGM Resorts | D750: 45962 | E750: 17352326 | F750: 1401234.1 | G750: 0.080751946
A751: IA | B751: BetMGM | C751: Entain/MGM Resorts | D751: 45992 | E751: 18094189 | F751: 1801453.9 | G751: 0.099559804
A752: IA | B752: BetMGM | C752: Entain/MGM Resorts | D752: 46023 | E752: 15713053 | F752: 1889342.5 | G752: 0.12024032
A753: IA | B753: BetMGM | C753: Entain/MGM Resorts | D753: 46054 | E753: 14406960 | F753: 1220178 | G753: 0.084693646
A754: IA | B754: BetMGM | C754: Entain/MGM Resorts | D754: 46082 | E754: 17123304 | F754: 1740343.8 | G754: 0.10163598
A755: IA | B755: Caesars | C755: Caesars Entertainment | D755: 44927 | E755: 35514714 | F755: 1729328 | G755: 0.048693282
... A822: IA | B822: DraftKings | C822: DraftKings Inc | D822: 45778 | E822: 58458.64 | F822: -361.71 | G822: -0.0061874515
A823: IA | B823: DraftKings | C823: DraftKings Inc | D823: 45809 | E823: 0 | F823: 0
A824: IA | B824: DraftKings | C824: DraftKings Inc | D824: 45839 | E824: 0 | F824: 0
A825: IA | B825: DraftKings | C825: DraftKings Inc | D825: 45870 | E825: 0 | F825: 0
A826: IA | B826: DraftKings | C826: DraftKings Inc | D826: 45901 | E826: 0 | F826: -633.26
...

Sheet Coverage
A1: COVERAGE — Month × State
A2: Each cell shows whether that state published online operator-level rows for that month. Months where a state is blank are excluded from that month's totals (denominator shrinks).
A4: Month | B4: AZ | C4: CT | D4: DC | E4: IA | F4: IL | G4: IN | H4: KS | I4: KY | J4: MA | K4: MD | L4: ME | M4: MI | N4: MO | O4: NH | P4: NJ | Q4: NY | R4: OH | S4: OR | T4: PA | U4: WV | V4: WY | W4: # States
A5: 43313 | P5: ✓ | W5: 1
A6: 43344 | P6: ✓ | W6: 1
A7: 43374 | P7: ✓ | W7: 1
A8: 43405 | P8: ✓ | W8: 1
A9: 43435 | P9: ✓ | W9: 1
A10: 43466 | P10: ✓ | W10: 1
A11: 43497 | P11: ✓ | W11: 1
A12: 43525 | P12: ✓ | W12: 1
A13: 43556 | P13: ✓ | W13: 1
A14: 43586 | P14: ✓ | T14: ✓ | W14: 2
A15: 43617 | P15: ✓ | T15: ✓ | W15: 2
A16: 43647 | P16: ✓ | T16: ✓ | W16: 2
A17: 43678 | E17: ✓ | P17: ✓ | T17: ✓ | W17: 3
A18: 43709 | E18: ✓ | T18: ✓ | W18: 2
A19: 43739 | E19: ✓ | G19: ✓ | P19: ✓ | T19: ✓ | W19: 4
A20: 43770 | E20: ✓ | G20: ✓ | P20: ✓ | T20: ✓ | W20: 4
A21: 43800 | E21: ✓ | G21: ✓ | O21: ✓ | P21: ✓ | T21: ✓ | W21: 5
A22: 43831 | E22: ✓ | G22: ✓ | O22: ✓ | P22: ✓ | S22: ✓ | T22: ✓ | W22: 6
A23: 43862 | E23: ✓ | G23: ✓ | O23: ✓ | P23: ✓ | S23: ✓ | T23: ✓ | W23: 6
A24: 43891 | E24: ✓ | F24: ✓ | G24: ✓ | O24: ✓ | P24: ✓ | S24: ✓ | T24: ✓ | W24: 7
A25: 43922 | E25: ✓ | F25: ✓ | G25: ✓ | O25: ✓ | P25: ✓ | S25: ✓ | T25: ✓ | W25: 7
A26: 43952 | E26: ✓ | F26: ✓ | G26: ✓ | O26: ✓ | P26: ✓ | S26: ✓ | T26: ✓ | W26: 7
A27: 43983 | E27: ✓ | F27: ✓ | G27: ✓ | O27: ✓ | P27: ✓ | S27: ✓ | T27: ✓ | U27: ✓ | W27: 8
A28: 44013 | E28: ✓ | F28: ✓ | G28: ✓ | O28: ✓ | P28: ✓ | S28: ✓ | T28: ✓ | U28: ✓ | W28: 8
A29: 44044 | E29: ✓ | F29: ✓ | G29: ✓ | O29: ✓ | P29: ✓ | S29: ✓ | T29: ✓ | U29: ✓ | W29: 8
A30: 44075 | E30: ✓ | F30: ✓ | G30: ✓ | O30: ✓ | P30: ✓ | S30: ✓ | T30: ✓ | U30: ✓ | W30: 8
A31: 44105 | E31: ✓ | F31: ✓ | G31: ✓ | O31: ✓ | P31: ✓ | S31: ✓ | T31: ✓ | U31: ✓ | W31: 8
A32: 44136 | E32: ✓ | F32: ✓ | G32: ✓ | O32: ✓ | P32: ✓ | S32: ✓ | T32: ✓ | U32: ✓ | W32: 8
A33: 44166 | E33: ✓ | F33: ✓ | G33: ✓ | O33: ✓ | P33: ✓ | S33: ✓ | T33: ✓ | U33: ✓ | W33: 8
A34: 44197 | E34: ✓ | F34: ✓ | G34: ✓ | M34: ✓ | O34: ✓ | P34: ✓ | T34: ✓ | U34: ✓ | W34: 8
A35: 44228 | E35: ✓ | F35: ✓ | G35: ✓ | M35: ✓ | O35: ✓ | P35: ✓ | S35: ✓ | T35: ✓ | U35: ✓ | W35: 9
A36: 44256 | E36: ✓ | F36: ✓ | G36: ✓ | M36: ✓ | O36: ✓ | P36: ✓ | S36: ✓ | T36: ✓ | U36: ✓ | W36: 9
A37: 44287 | E37: ✓ | F37: ✓ | G37: ✓ | M37: ✓ | O37: ✓ | P37: ✓ | Q37: ✓ | S37: ✓ | T37: ✓ | U37: ✓ | W37: 10
A38: 44317 | E38: ✓ | F38: ✓ | G38: ✓ | M38: ✓ | O38: ✓ | P38: ✓ | Q38: ✓ | S38: ✓ | T38: ✓ | U38: ✓ | W38: 10
A39: 44348 | E39: ✓ | F39: ✓ | G39: ✓ | M39: ✓ | O39: ✓ | P39: ✓ | Q39: ✓ | S39: ✓ | T39: ✓ | U39: ✓ | W39: 10
A40: 44378 | E40: ✓ | F40: ✓ | G40: ✓ | M40: ✓ | O40: ✓ | P40: ✓ | Q40: ✓ | S40: ✓ | T40: ✓ | U40: ✓ | W40: 10
A41: 44409 | E41: ✓ | F41: ✓ | G41: ✓ | M41: ✓ | O41: ✓ | P41: ✓ | Q41: ✓ | S41: ✓ | T41: ✓ | U41: ✓ | W41: 10
...

Sheet Sources
A1: State | B1: State Name | C1: Regulator | D1: Source Landing Page | E1: Report Frequency | F1: File Format | G1: Launch Date
A2: AZ | B2: Arizona | C2: Arizona Department of Gaming | D2: https://gaming.az.gov/blog-terms/event-wagering-revenue-reports | E2: monthly | F2: pdf | G2: 2021-09-09
A3: CT | B3: Connecticut | C3: CT DCP Gaming Division | D3: https://data.ct.gov/api/views/xf6g-659c/rows.csv?accessType=DOWNLOAD | E3: monthly | F3: csv | G3: 2021-10-19
A4: DC | B4: District of Columbia | C4: DC Office of Lottery and Gaming | D4: https://dclottery.com/olg/financials | E4: monthly | F4: html | G4: 2020-05-28
A5: IA | B5: Iowa | C5: Iowa Racing and Gaming Commission | D5: https://irgc.iowa.gov/publications-reports/sports-wagering-revenue | E5: monthly | F5: pdf | G5: 2019-08-15
A6: IL | B6: Illinois | C6: Illinois Gaming Board | D6: https://igb.illinois.gov/sports-wagering/sports-reports.html | E6: monthly | F6: csv | G6: 2020-03-09
A7: IN | B7: Indiana | C7: Indiana Gaming Commission | D7: https://www.in.gov/igc/publications/monthly-revenue/ | E7: monthly | F7: xlsx | G7: 2019-09-01
A8: KS | B8: Kansas | C8: Kansas Lottery | D8: https://www.kslottery.com/publications/sports-monthly-revenues/ | E8: monthly | F8: pdf | G8: 2022-09-01
A9: KY | B9: Kentucky | C9: KY Horse Racing Commission | D9: https://khrc.ky.gov/newstatic_info.aspx?static_ID=694 | E9: monthly | F9: pdf | G9: 2023-09-28
A10: MA | B10: Massachusetts | C10: Massachusetts Gaming Commission | D10: https://massgaming.com/regulations/revenue/ | E10: monthly | F10: pdf | G10: 2023-01-31
A11: MD | B11: Maryland | C11: Maryland Lottery and Gaming Control Agency | D11: https://www.mdgaming.com/maryland-sports-wagering/revenue-reports/ | E11: monthly | F11: html | G11: 2021-12-10
A12: ME | B12: Maine | C12: Maine Gambling Control Unit | D12: https://www.maine.gov/dps/gcu/sports-wagering/sports-wagering-revenue | E12: monthly | F12: pdf | G12: 2023-11-03
... A22: WY | B22: Wyoming | C22: Wyoming Gaming Commission | D22: https://gaming.wyo.gov/revenue-reports/financial-reports/combined-wagering-activity-reports | E22: monthly | F22: pdf | G22: 2021-09-01

Sheet Methodology
A1: Note
A2: SCOPE: Online channel only. Retail and combined channels excluded.
A3: TIME WINDOW: All time (since each state's online launch).
A4: STATES INCLUDED (21): AZ, CT, DC, IA, IL, IN, KS, KY, MA, MD, ME, MI, MO, NH, NJ, NY, OH, OR, PA, WV, WY.
A5: STATES EXCLUDED — no operator-level online breakdown: AR, CO, DE, LA, MS, MT, NC, NE, NV, RI, SD, TN, VA, VT.
A6: NH and OR are DraftKings monopolies (state-exclusive contracts) — all of each state's online handle/GGR rolls into the DraftKings bucket.
A7: ME is a tribal-compact 2-operator market (DraftKings + Caesars).
A8: BUCKETS (fixed): FanDuel, DraftKings, BetMGM, Fanatics, Caesars, ESPN Bet, Others. Barstool history is already merged into ESPN Bet via the upstream operator_standard mapping.
A9: GGR DEFINITION: standard_ggr = handle − payouts. Normalized across states.
A10: HOLD: GGR / Handle, computed at the bucket level.
A11: MARKET SHARE: bucket / state-month total. States that did not publish a given month are excluded from that month's denominator — see Coverage sheet.
A12: Y/Y GROWTH: current month / same month prior year − 1. Cells before the first available prior-year month are blank.
... A20: KY: 2025+ data sourced from KHRC Tableau dashboard via OCR.
